Traceback (most recent call last):
  File "/opt/conda/lib/python3.11/site-packages/huggingface_hub/utils/_http.py", line 406, in hf_raise_for_status
    response.raise_for_status()
  File "/opt/conda/lib/python3.11/site-packages/requests/models.py", line 1024, in raise_for_status
    raise HTTPError(http_error_msg, response=self)
requests.exceptions.HTTPError: 401 Client Error: Unauthorized for url: https://huggingface.co/meta-llama/Llama-3.2-1B-Instruct/resolve/main/config.json

The above exception was the direct cause of the following exception:

Traceback (most recent call last):
  File "/opt/conda/lib/python3.11/site-packages/transformers/utils/hub.py", line 403, in cached_file
    resolved_file = hf_hub_download(
                    ^^^^^^^^^^^^^^^^
  File "/opt/conda/lib/python3.11/site-packages/huggingface_hub/utils/_validators.py", line 114, in _inner_fn
    return fn(*args, **kwargs)
           ^^^^^^^^^^^^^^^^^^^
  File "/opt/conda/lib/python3.11/site-packages/huggingface_hub/file_download.py", line 860, in hf_hub_download
    return _hf_hub_download_to_cache_dir(
           ^^^^^^^^^^^^^^^^^^^^^^^^^^^^^^
  File "/opt/conda/lib/python3.11/site-packages/huggingface_hub/file_download.py", line 967, in _hf_hub_download_to_cache_dir
    _raise_on_head_call_error(head_call_error, force_download, local_files_only)
  File "/opt/conda/lib/python3.11/site-packages/huggingface_hub/file_download.py", line 1482, in _raise_on_head_call_error
    raise head_call_error
  File "/opt/conda/lib/python3.11/site-packages/huggingface_hub/file_download.py", line 1374, in _get_metadata_or_catch_error
    metadata = get_hf_file_metadata(
               ^^^^^^^^^^^^^^^^^^^^^
  File "/opt/conda/lib/python3.11/site-packages/huggingface_hub/utils/_validators.py", line 114, in _inner_fn
    return fn(*args, **kwargs)
           ^^^^^^^^^^^^^^^^^^^
  File "/opt/conda/lib/python3.11/site-packages/huggingface_hub/file_download.py", line 1294, in get_hf_file_metadata
    r = _request_wrapper(
        ^^^^^^^^^^^^^^^^^
  File "/opt/conda/lib/python3.11/site-packages/huggingface_hub/file_download.py", line 278, in _request_wrapper
    response = _request_wrapper(
               ^^^^^^^^^^^^^^^^^
  File "/opt/conda/lib/python3.11/site-packages/huggingface_hub/file_download.py", line 302, in _request_wrapper
    hf_raise_for_status(response)
  File "/opt/conda/lib/python3.11/site-packages/huggingface_hub/utils/_http.py", line 423, in hf_raise_for_status
    raise _format(GatedRepoError, message, response) from e
huggingface_hub.errors.GatedRepoError: 401 Client Error. (Request ID: Root=1-67a71d70-42ef076f20b5503866a28dcb;67680043-fd95-4f9c-a633-8872d582ef2e)

Cannot access gated repo for url https://huggingface.co/meta-llama/Llama-3.2-1B-Instruct/resolve/main/config.json.
Access to model meta-llama/Llama-3.2-1B-Instruct is restricted. You must have access to it and be authenticated to access it. Please log in.

The above exception was the direct cause of the following exception:

Traceback (most recent call last):
  File "/root/fine_tuning_Llama/scripts/train.py", line 369, in <module>
    main()
  File "/root/fine_tuning_Llama/scripts/train.py", line 292, in main
    config = AutoConfig.from_pretrained(
             ^^^^^^^^^^^^^^^^^^^^^^^^^^^
  File "/opt/conda/lib/python3.11/site-packages/transformers/models/auto/configuration_auto.py", line 1054, in from_pretrained
    config_dict, unused_kwargs = PretrainedConfig.get_config_dict(pretrained_model_name_or_path, **kwargs)
                                 ^^^^^^^^^^^^^^^^^^^^^^^^^^^^^^^^^^^^^^^^^^^^^^^^^^^^^^^^^^^^^^^^^^^^^^^^^
  File "/opt/conda/lib/python3.11/site-packages/transformers/configuration_utils.py", line 591, in get_config_dict
    config_dict, kwargs = cls._get_config_dict(pretrained_model_name_or_path, **kwargs)
                          ^^^^^^^^^^^^^^^^^^^^^^^^^^^^^^^^^^^^^^^^^^^^^^^^^^^^^^^^^^^^^
  File "/opt/conda/lib/python3.11/site-packages/transformers/configuration_utils.py", line 650, in _get_config_dict
    resolved_config_file = cached_file(
                           ^^^^^^^^^^^^
  File "/opt/conda/lib/python3.11/site-packages/transformers/utils/hub.py", line 421, in cached_file
    raise EnvironmentError(
OSError: You are trying to access a gated repo.
Make sure to have access to it at https://huggingface.co/meta-llama/Llama-3.2-1B-Instruct.
401 Client Error. (Request ID: Root=1-67a71d70-42ef076f20b5503866a28dcb;67680043-fd95-4f9c-a633-8872d582ef2e)

Cannot access gated repo for url https://huggingface.co/meta-llama/Llama-3.2-1B-Instruct/resolve/main/config.json.
Access to model meta-llama/Llama-3.2-1B-Instruct is restricted. You must have access to it and be authenticated to access it. Please log in.
